Workbook

Sheet Strona tytulowa
B2: DINO POLSKA S.A.
B3: Model finansowy — analiza wskaźnikowa 2021-2024
B5: Spółka | C5: Dino Polska S.A.
B6: Okres analizy | C6: 2021-2024 (dane jednostkowe)
B7: Waluta | C7: tys. PLN, chyba że wskazano inaczej
B8: Autor | C8: Daryna Akkus
B9: Status | C9: Portfolio project
B11: NAWIGACJA
B12: -> Bilans | C12: Analiza struktury i dynamiki aktywów oraz pasywów, złota/srebrna reguła bilansowa
B13: -> RZiS | C13: Rachunek zysków i strat — struktura przychodów i kosztów, analiza pionowa/pozioma
B14: -> Przepływy pieniężne | C14: Rachunek przepływów pieniężnych (metoda pośrednia) za 2021-2024
B15: -> Wskaźniki finansowe | C15: Płynność, zadłużenie, rentowność (ROS/ROA/ROE), sprawność działania, DuPont
B16: -> Benchmarking | C16: Porównanie z Żabka Group i Biedronka (Jerónimo Martins)
B17: -> Sieć sklepów | C17: Dynamika liczby sklepów i powierzchni sprzedaży 2015-2024
B19: KONWENCJA KOLORÓW
B20: Niebieski tekst | C20: Dane wejściowe (hardcoded) — wartości ze sprawozdań finansowych
B21: Czarny tekst | C21: Formuły i obliczenia wewnątrz arkusza
B22: Zielony tekst | C22: Odwołania (linki) do innych arkuszy w skoroszycie
B24: Źródło danych | C24: Sprawozdania finansowe jednostkowe Dino Polska S.A. za lata 2021-2024 (grupadino.pl)

Sheet Bilans
A1: bilans | B1: 2021 | C1: 2022 | D1: 2023 | E1: 2024
A2: aktywa razem | B2: =B3+B11 -> 7168531 | C2: =C3+C11 -> 9003059 | D2: =D3+D11 -> 10377715 | E2: =E3+E11 -> 13055794
A3: aktywa trwałe | B3: =SUM(B4:B8) -> 5183347 | C3: =SUM(C4:C8) -> 6296353 | D3: =SUM(D4:D8) -> 7124550 | E3: 8616378
I4: 2021 | J4: 2022 | K4: 2023 | L4: 2024
A5: Rzeczowe aktywa trwałe | B5: 4911353 | C5: 6070032 | D5: 6874672 | E5: 8230915 | H5: Rzeczowe aktywa trwałe | I5: =B5/B$3 -> 0.94752541 | J5: =C5/C$3 -> 0.96405522 | K5: =D5/D$3 -> 0.96492719 | L5: =E5/E$3 -> 0.95526392
A6: Aktywa z tytułu prawa do użytkowania | B6: 139931 | C6: 105116 | D6: 93499 | E6: 141350 | H6: Aktywa z tytułu prawa do użytkowania | I6: =B6/B$3 -> 0.026996263 | J6: =C6/C$3 -> 0.016694744 | K6: =D6/D$3 -> 0.013123496 | L6: =E6/E$3 -> 0.016404805
A7: Aktywa niematerialne | B7: 96947 | C7: 94737 | D7: 115056 | E7: 169964 | H7: Aktywa niematerialne | I7: =B7/B$3 -> 0.018703552 | J7: =C7/C$3 -> 0.015046329 | K7: =D7/D$3 -> 0.01614923 | L7: =E7/E$3 -> 0.01972569
A8: Aktywa z tytułu podatku odroczonego | B8: 35116 | C8: 26468 | D8: 41323 | E8: 74149 | H8: Aktywa z tytułu podatku odroczonego | I8: =B8/B$3 -> 0.0067747731 | J8: =C8/C$3 -> 0.0042037033 | K8: =D8/D$3 -> 0.0058000856 | L8: =E8/E$3 -> 0.0086055881
A11: B. Aktywa obrotowe | B11: =SUM(B12:B17) -> 1985184 | C11: =SUM(C12:C17) -> 2706706 | D11: =SUM(D12:D17) -> 3253165 | E11: =SUM(E12:E17) -> 4439416
A12: Zapasy | B12: 1373463 | C12: 1978778 | D12: 2638859 | E12: 3081444 | I12: 2021 | J12: 2022 | K12: 2023 | L12: 2024
A13: Należności z tytułu dostaw i usług oraz pozostałe | B13: 144012 | C13: 274872 | D13: 330389 | E13: 376480 | H13: Zapasy | I13: =B12/B$11 -> 0.69185677 | J13: =C12/C$11 -> 0.73106499 | K13: =D12/D$11 -> 0.81116666 | L13: =E12/E$11 -> 0.69411022
A14: Należności z tytułu podatku dochodowego | B14: 55 | C14: 0 | D14: 103 | E14: 220 | H14: Należności z tytułu dostaw i usług oraz pozostałe | I14: =B13/B$11 -> 0.072543402 | J14: =C13/C$11 -> 0.10155222 | K14: =D13/D$11 -> 0.10155925 | L14: =E13/E$11 -> 0.084803947
A15: Pozostałe aktywa niefinansowe | B15: 47712 | C15: 69096 | D15: 64049 | E15: 88186 | H15: Należności z tytułu podatku dochodowego | I15: =B14/B$11 -> 2.770524e-05 | J15: =C14/C$11 -> 0 | K15: =D14/D$11 -> 3.1661474e-05 | L15: =E14/E$11 -> 4.9556068e-05
A16: Pozostałe aktywa finansowe | B16: 1327 | C16: 1242 | D16: 1376 | E16: 2064 | H16: Pozostałe aktywa niefinansowe | I16: =B15/B$11 -> 0.024034044 | J16: =C15/C$11 -> 0.025527708 | K16: =D15/D$11 -> 0.019688211 | L16: =E15/E$11 -> 0.019864324
A17: Środki pieniężne i ich ekwiwalenty | B17: 418615 | C17: 382718 | D17: 218389 | E17: 891022 | H17: Pozostałe aktywa finansowe | I17: =B16/B$11 -> 0.00066845189 | J17: =C16/C$11 -> 0.00045886033 | K17: =D16/D$11 -> 0.00042297271 | L17: =E16/E$11 -> 0.00046492602
H18: Środki pieniężne i ich ekwiwalenty | I18: =B17/B$11 -> 0.21086962 | J18: =C17/C$11 -> 0.14139622 | K18: =D17/D$11 -> 0.06713124 | L18: =E17/E$11 -> 0.20070703
A20: P A S Y W A | B20: =SUM(B21,B29,B37) -> 7168531 | C20: =SUM(C21,C28,C29,C37) -> 9003059 | D20: =SUM(D21,D29,D37) -> 10377715 | E20: =SUM(E21,E29,E37,E28) -> 13055794
A21: Kapitały własne przypadający akcjonariuszom domin. | B21: =SUM(B22:B28) -> 3070190 | C21: =SUM(C22:C28) -> 4203783 | D21: =SUM(D22:D28) -> 5605311 | E21: =SUM(E22:E25) -> 7085151
A22: Kapitał podstawowy | B22: 9804 | C22: 9804 | D22: 9804 | E22: 9804 | I22: 2021 | J22: 2022 | K22: 2023 | L22: 2024
A23: kapitał zapasowy | B23: 2707720 | C23: 3512022 | D23: 4652148 | E23: 6058912 | H23: Kapitały własne przypadający akcjonariuszom domin. | I23: 3070190 | J23: 4203783 | K23: 5605311 | L23: 7085151
A24: Zyski zatrzymane | B24: 345166 | C24: 674457 | D24: 935859 | E24: 1031871 | H24: Zobowiązania długoterminowe | I24: 1092804 | J24: 1109149 | K24: 893111 | L24: 570511
A25: Pozostałe kapitały własne | B25: 7500 | C25: 7500 | D25: 7500 | E25: -15436 | H25: Zobowiązania krótkoterminowe | I25: 3005537 | J25: 3690127 | K25: 3879293 | L25: 5382849
A28: Udziały nie dające kontroli | B28: 0 | C28: 0 | E28: 17283 | I28: 2021 | J28: 2022 | K28: 2023 | L28: 2024
A29: C. Zobowiązania długoterminowe | B29: =SUM(B30:B36) -> 1092804 | C29: =SUM(C30:C36) -> 1109149 | D29: =SUM(D30:D36) -> 893111 | E29: =SUM(E30:E36) -> 570511 | H29: Kapitały własne przypadający akcjonariuszom domin. | I29: =I23/B$20 -> 0.42828719 | J29: =J23/C$20 -> 0.4669283 | K29: =K23/D$20 -> 0.5401296 | L29: =L23/E$20 -> 0.54268251
A30: Kredyty bankowe | B30: 583014 | C30: 690862 | D30: 469629 | E30: 272219 | H30: Zobowiązania długoterminowe | I30: =I24/B$20 -> 0.15244462 | J30: =J24/C$20 -> 0.1231969 | K30: =K24/D$20 -> 0.086060467 | L30: =L24/E$20 -> 0.043697917
A31: Zobowiązania z tytułu leasingu | B31: 46621 | C31: 34673 | D31: 35612 | E31: 60818 | H31: Zobowiązania krótkoterminowe | I31: =I25/B$20 -> 0.41926819 | J31: =J25/C$20 -> 0.4098748 | K31: =K25/D$20 -> 0.37380994 | L31: =L25/E$20 -> 0.4122958
A32: Zobowiązania z tytułu wyemitowanych obligacji | B32: 450000 | C32: 370000 | D32: 370000 | E32: 170000
A33: Zobowiązania do nabycia udziałów niekontrolujących | E33: 22936
A34: Zobowiązania z tytułu świadczeń pracowniczych | B34: 4827 | C34: 5794 | D34: 10900 | E34: 14142
A35: Pozostałe zobowiązania | B35: 155 | C35: 120 | D35: 90 | E35: 60
A36: Rezerwa z tytułu odroczonego podatku dochodowego | B36: 8187 | C36: 7700 | D36: 6880 | E36: 30336
A37: D. Zobowiązania krótkoterminowe | B37: =SUM(B38:B44) -> 3005537 | C37: =SUM(C38:C44) -> 3690127 | D37: =SUM(D38:D44) -> 3879293 | E37: =SUM(E38:E44) -> 5382849
A38: Zobowiązania z tytułu dostaw i usług | B38: 2454051 | C38: 2794077 | D38: 3095968 | E38: 4362006
A39: Kredyty bankowe | B39: 196169 | C39: 410157 | D39: 278588 | E39: 361034
A40: Zobowiązania z tyt. Leasingu | B40: 27721 | C40: 17893 | D40: 14565 | E40: 17900
A41: Zobowiązania z tytułu wyemitowanych obligacji | B41: 171642 | C41: 260947 | D41: 4784 | E41: 204845
A42: Zobowiązania z tytułu świadczeń pracowniczych | B42: 1944 | C42: 965 | D42: 307273 | E42: 382575
A43: Zobowiązania z tytułu podatku dochodowego | B43: 93017 | C43: 120034 | D43: 176736 | E43: 50612
A44: Przychody przyszłych okresów | B44: 60993 | C44: 86054 | D44: 1379 | E44: 3877
A51: STRUKTURA KAPITAŁOWO-MAJĄTKOWA
...

Sheet RZiS
B2: TREŚĆ | C2: Rok
C3: 2021 | E3: 2022 | I3: 2023 | M3: 2024 | S3: 2021 | T3: 2022 | U3: 2023 | V3: 2024
C4: Suma | D4: Struktura % | E4: Suma | F4: Zmiany | H4: Struktura % | I4: Suma | J4: Zmiany | L4: Struktura % | M4: Suma | N4: Zmiany | P4: Struktura % | R4: Koszty sprzedaży | S4: 2181963 | T4: 3080061 | U4: 3878421 | V4: 4678717
C5: tys. zł | E5: tys. zł | F5: tys. zł | G5: Tempo % | I5: tys. zł | J5: tys. zł | K5: Tempo % | M5: tys. zł | N5: tys. zł | O5: Tempo % | R5: Koszty zarządu | S5: 117285 | T5: 143217 | U5: 173736 | V5: 233653
B6: Przychody ze sprzedaży | C6: 13362012 | D6: 1 | E6: 19801622 | F6: 6439610 | G6: 0.48193416 | H6: 1 | I6: 25666255 | J6: 5864633 | K6: 0.29616932 | L6: 1 | M6: 29273792 | N6: 3607537 | O6: 0.14055564 | P6: 1
B7: Koszt własny sprzedaży | C7: 10038342 | D7: 0.75125977 | E7: 15038630 | F7: 5000288 | G7: 0.49811891 | H7: 0.75946455 | I7: 19741459 | J7: 4702829 | K7: 0.31271658 | L7: 0.76916009 | M7: 22463233 | N7: 2721774 | O7: 0.13787096 | P7: 0.76734961
B8: Zysk (strata) na sprzedaży | C8: 3323670 | D8: 0.24874023 | E8: 4762992 | F8: 1439322 | G8: 0.43305202 | H8: 0.24053545 | I8: 5924796 | J8: 1161804 | K8: 0.24392315 | L8: 0.23083991 | M8: 6810559 | N8: 885763 | O8: 0.14950101 | P8: 0.23265039
B9: Koszty sprzedaży | C9: 2181963 | D9: 0.16329599 | E9: 3080061 | F9: 898098 | G9: 0.41160093 | H9: 0.15554589 | I9: 3878421 | J9: 798360 | K9: 0.25920266 | L9: 0.15110974 | M9: 4678717 | N9: 800296 | O9: 0.20634583 | P9: 0.15982613
B10: Koszty zarządu | C10: 117285 | D10: 0.0087774955 | E10: 143217 | F10: 25932 | G10: 0.22110244 | H10: 0.0072325893 | I10: 173736 | J10: 173736 | K10: 1.2130962 | L10: 0.0067690436 | M10: 233653 | N10: 59917 | O10: 0.34487383 | P10: 0.0079816445
B11: Pozostałe przychody operacyjne | C11: 14364 | D11: 0.0010749878 | E11: 16282 | F11: 1918 | H11: 0.00082225587 | I11: 13477 | J11: -2805 | K11: -0.17227613 | L11: 0.00052508634 | M11: 24185 | N11: 10708 | O11: 0.79453884 | P11: 0.0008261656
B12: Pozostałe koszty operacyjne | C12: 14793 | D12: 0.0011070938 | E12: 18177 | F12: 3384 | H12: 0.0009179551 | I12: 10261 | J12: -7916 | K12: -0.43549541 | L12: 0.00039978563 | M12: 14044 | N12: 3783 | O12: 0.36867752 | P12: 0.00047974653
B13: Zysk (strata) z działalności operacyjnej | C13: 1023993 | D13: 0.076634642 | E13: 1537819 | F13: 513826 | G13: 0.50178663 | H13: 0.077661264 | I13: 1875855 | J13: 338036 | K13: 0.21981521 | L13: 0.073086432 | M13: 1908330 | N13: 32475 | O13: 0.017312106 | P13: 0.065189026
B14: Przychody finansowe | C14: 1119 | D14: 8.3744873e-05 | E14: 5092 | F14: 3973 | G14: 3.5504915 | H14: 0.00025715065 | I14: 10442 | J14: 5350 | K14: 1.0506677 | L14: 0.00040683769 | M14: 6657 | N14: -3785 | O14: -0.36247845 | P14: 0.00022740477
B15: Koszty finansowe | C15: 46703 | D15: 0.0034952072 | E15: 141293 | F15: 94590 | G15: 2.0253517 | H15: 0.0071354256 | I15: 147316 | J15: 6023 | K15: 0.042627731 | L15: 0.0057396765 | M15: 121424 | N15: -25892 | O15: -0.17575823 | P15: 0.004147874
B16: Zysk /strata na działalności gospodarczej – z/s brutto | C16: 978409 | D16: 0.073223179 | E16: 1401618 | F16: 423209 | G16: 0.43254815 | H16: 0.070782989 | I16: 1738981 | J16: 337363 | K16: 0.2406954 | L16: 0.067753593 | M16: 1793563 | N16: 54582 | O16: 0.031387347 | P16: 0.061268557
B17: Podatek dochodowy | C17: 173106 | D17: 0.012955085 | E17: 269531 | F17: 96425 | G17: 0.55702864 | H17: 0.013611562 | I17: 333654 | J17: 64123 | K17: 0.23790584 | L17: 0.012999715 | M17: 287834 | N17: -45820 | O17: -0.13732789 | P17: 0.0098324809
B18: Zysk strata netto | C18: 805303 | D18: 0.060268094 | E18: 1132087 | F18: 326784 | G18: 0.40579012 | H18: 0.057171428 | I18: 1405327 | J18: 273240 | K18: 0.24135954 | L18: 0.054753878 | M18: 1505729 | N18: 100402 | O18: 0.07144387 | P18: 0.051436076
I21: Rok | J21: 2021 | K21: 2022 | L21: 2023 | M21: 2024
J22: tys. zł | K22: tys. zł | L22: tys. zł | M22: tys. zł
I23: Przychody ze sprzedaży | J23: 13362012 | K23: 19801622 | L23: 25666255 | M23: 29273792
I38: Tempo wzrostu przychodow ze sprzedaży | K38: 2022 | L38: 2023 | M38: 2024
I39: Przychody ze sprzedaży | K39: 0.48 | L39: 0.3 | M39: 0.14
J44: 2021 | K44: 2022 | L44: 2023 | M44: 2024
I45: Koszt własny sprzedaży | J45: 10038342 | K45: 15038630 | L45: 19741459 | M45: 22463233 | S45: 2021 | T45: 2022 | U45: 2023 | V45: 2024
R46: Zysk (strata) z działalności operacyjnej | S46: 0.08 | T46: 0.08 | U46: 0.07 | V46: 0.065
R47: Zysk strata netto | S47: 0.06 | T47: 0.06 | U47: 0.05 | V47: 0.051
K49: 2022 | L49: 2023 | M49: 2024
I50: Koszt własny sprzedaży | K50: 0.5 | L50: 0.31 | M50: 0.14
C85: 2021 | D85: % | E85: 2022 | F85: % | I85: 2023 | J85: % | M85: 2024 | N85: %
B86: Koszt własny sprzedaży | C86: 10038342 | D86: =C86/C91 -> 0.80960339 | E86: 15038630 | F86: =E86/E91 -> 0.81636835 | I86: 19741459 | J86: =I86/I91 -> 0.82423698 | M86: 22463233 | N86: =M86/M91 -> 0.81651612
B87: Koszty sprzedaży | C87: 2181963 | D87: =C87/C91 -> 0.17597773 | E87: 3080061 | F87: =E87/E91 -> 0.16720036 | I87: 3878421 | J87: =I87/I91 -> 0.16193018 | M87: 4678717 | N87: =M87/M91 -> 0.1700667
B88: Koszty zarządu | C88: 117285 | D88: =C88/C91 -> 0.009459165 | E88: 143217 | F88: =E88/E91 -> 0.0077744998 | I88: 173736 | J88: =I88/I91 -> 0.0072537514 | M88: 233653 | N88: =M88/M91 -> 0.0084930536
B89: Pozostałe koszty operacyjne | C89: 14793 | D89: =C89/C91 -> 0.0011930718 | E89: 18177 | F89: =E89/E91 -> 0.000986734 | I89: 10261 | J89: =I89/I91 -> 0.0004284129 | M89: 14044 | N89: =M89/M91 -> 0.0005104854
B90: Koszty finansowe | C90: 46703 | D90: =C90/C91 -> 0.0037666486 | E90: 141293 | F90: =E90/E91 -> 0.007670056 | I90: 147316 | J90: =I90/I91 -> 0.0061506748 | M90: 121424 | N90: =M90/M91 -> 0.0044136413
B91: SUMA | C91: =SUM(C86:C90) -> 12399086 | E91: =SUM(E86:E90) -> 18421378 | I91: =SUM(I86:I90) -> 23951193 | M91: =SUM(M86:M90) -> 27511071
C96: 2021 | D96: 2022 | E96: 2023 | F96: 2024 | H96: srednia | I96: 2021-2024
B97: Koszt własny sprzedaży | C97: 0.80960339 | D97: 0.81636835 | E97: 0.82423698 | F97: 0.81651612 | H97: Koszt własny sprzedaży | I97: =AVERAGE(C97:F97) -> 0.81668121
B98: Koszty sprzedaży | C98: 0.17597773 | D98: 0.16720036 | E98: 0.16193018 | F98: 0.1700667 | H98: Koszty sprzedaży | I98: =AVERAGE(C98:F98) -> 0.16879374
B99: Koszty zarządu | C99: 0.009459165 | D99: 0.0077744998 | E99: 0.0072537514 | F99: 0.0084930536 | H99: Koszty zarządu | I99: =AVERAGE(C99:F99) -> 0.0082451174
B100: Pozostałe koszty operacyjne | C100: 0.0011930718 | D100: 0.000986734 | E100: 0.0004284129 | F100: 0.0005104854 | H100: Pozostałe koszty operacyjne | I100: =AVERAGE(C100:F100) -> 0.00077967603
...

Sheet Benchmarking
A1: Przychody ze sprzedaży | B1: 2021 | C1: 2022 | D1: 2023 | E1: 2024 | F1: CAGR 21-24 | H1: Kursy walutowe użyte do przeliczeń (EUR/PLN, NBP) | I1: 2021 | J1: 2022 | K1: 2023 | L1: 2024
A2: Dino Polska S.A. | B2: 13362 | C2: 19801.6 | D2: 25666.3 | E2: 29273.8 | F2: 0.298 | H2: Kurs średnioroczny EUR/PLN (NBP) | I2: 4,57* | J2: 4,69* | K2: 4,54* | L2: 4,31*
A3: Żabka Group | B3: 12493 | C3: 16003 | D3: 19806 | E3: 23797 | F3: 0.239 | G3: mln zlt | H3: *do potwierdzenia na nbp.pl — wartości orientacyjne, wymagają weryfikacji przed finalizacją raportu
A4: Biedronka ** | B4: 66456 | C4: 82460 | D4: 97610 | E4: 101591 | F4: 0.151
A5: *Żabka Group: dane szacunkowe za 2021 r., na podstawie dynamiki wzrostu 2022.
A6: **Biedronka: dane stanowią wyodrębniony segment geograficzny Grupy Jerónimo Martins (segment reporting), przeliczone z EUR na PLN według średniorocznych kursów NBP — zob. tabela kursów walutowych poniżej.
A7: Dynamika przychodów r/r (%) | B7: 2021 | C7: 2022 | D7: 2023 | E7: 2024 | G7: Źrodła
A8: Dino Polska S.A. | B8: - | C8: 0.482 | D8: 0.296 | E8: 0.141 | G8: Spółka | H8: Dokument źródłowy | I8: Zakres lat | J8: Link
A9: Żabka Group | B9: - | C9: 0.281 | D9: 0.238 | E9: 0.202 | G9: Dino Polska S.A. | H9: Sprawozdania finansowe jednostkowe (dane własne z projektu) | I9: 2021-2024 | J9: Dane własne — Sprawozdanie z analizy finansowej Dino Polska S.A., rozdziały 2–3 (na podstawie jednostkowych sprawozdań finansowych Spółki za lata 2021–2024)
A10: Biedronka | B10: - | C10: 0.241 | D10: 0.184 | E10: 0.041 | G10: Żabka Group | H10: Zabka Group 2024 Annual Report (Full Year) | I10: 2021-2024 | J10: https://zabkagroup.com/wp-content/uploads/2025/03/Zabka-Group-2024-AR-Full-year.pdf | K10: https://zabkagroup.com/wp-content/uploads/2026/06/202604_Zabka-Investors_WWW.pdf
G11: Biedronka (Jerónimo Martins) | H11: Jerónimo Martins Annual Report 2024 (segment reporting) | I11: 2021-2024 | J11: https://live.euronext.com/sites/default/files/company_press_releases/attachments/2025/03/27/Connect_annualreport-jm2024nonesef.pdf
G12: Kursy walut | H12: Tabela kursów średnich NBP (archiwum) | I12: 2021-2024 | J12: https://nbp.pl/statystyka-i-sprawozdawczosc/kursy/archiwum-tabela-a-csv-xls/
A13: Marża EBIT operacyjna | B13: 2021 | C13: 2022 | D13: 2023 | E13: 2024
A14: Dino Polska S.A. | B14: 0.08 | C14: 0.08 | D14: 0.07 | E14: 0.065
A15: Żabka Group | B15: n/d | C15: 0.076 | D15: 0.07 | E15: 0.07
A16: Biedronka | B16: 0.092 | C16: 0.088 | D16: 0.085 | E16: 0.077
A19: Rentowność sprzedaży (ROS/ marza netto) | B19: 2021 | C19: 2022 | D19: 2023 | E19: 2024
A20: Dino Polska S.A. | B20: 0.06 | C20: 0.057 | D20: 0.055 | E20: 0.051
A21: Żabka Group | B21: n/d | C21: 0.024 | D21: 0.018 | E21: 0.0249
A22: Biedronka | B22: n/d | C22: n/d | D22: n/d | E22: n/d
A25: Liczba punktów sprzedaży (sklepów) | B25: 2021 | C25: 2022 | D25: 2023 | E25: 2024 | F25: Revenue per Store 2024 rok
A26: Dino Polska S.A. | B26: 1815 | C26: 2156 | D26: 2406 | E26: 2688 | F26: =E2/E26 -> 10.890551
A27: Żabka Group | B27: 7954 | C27: 9021 | D27: 10014 | E27: 11069 | F27: =E3/E27 -> 2.149878
A28: Biedronka | B28: 3250 | C28: 3395 | D28: 3569 | E28: 3730 | F28: =E4/E28 -> 27.236193

Sheet Przepływy pieniężne
A1: WYSZCZEGÓLNIENIE | B1: 2021 | C1: 2022 | D1: 2023 | E1: 2024 | H1: 2021 | I1: 2022 | J1: 2023 | K1: 2024
A2: A.PRZEPŁYWY ŚRODKÓW PIENIĘŻNYCH Z DZIAŁALNOŚCI OPERACYJNEJ | G2: Przepływy pieniężne z działalności operacyjnej | H2: 1326331 | I2: 1253422 | J2: 1771540 | K2: 2557453
A3: (metoda pośrednia)
A4: I Zysk (strata) brutto | B4: 978409 | C4: 1401618 | D4: 1738981 | E4: 1793563
A5: II Korekty razem | B5: =SUM(B6:B16) -> 347922 | C5: =SUM(C6:C16) -> -148196 | D5: =SUM(D6:D16) -> 32559 | E5: =SUM(E6:E16) -> 763890
A6: Amortyzacja | B6: 247343 | C6: 300129 | D6: 356828 | E6: 409179
A7: zysk/strata na działalności inwestycyjnej | B7: 7423 | C7: 14540 | D7: 6531 | E7: 10372
A8: Przychody z tyt. Odsetek | B8: -998 | C8: -4969 | D8: -9006 | E8: -6101
A9: Koszty z tytułu odsetek | B9: 46645 | C9: 141293 | D9: 147316 | E9: 121353
A10: Zmiana stanu zapasów | B10: -498316 | C10: -605315 | D10: -660081 | E10: -424123
A11: zmiana stanu należności | B11: -24880 | C11: -152796 | D11: -54245 | E11: -55966
A12: Zmiana stanu zobowiązań krótkoterminowych ( z wyjątkiem pożyczek i kredytów | B12: 728449 | C12: 366502 | D12: 537055 | E12: 1126352
A13: Zmiana stanu rozliczeń międzyokresowych | B13: 14733 | C13: 25226
A14: zmiana stanu rezerw | B14: 2595 | C14: -12
A15: Pozostałe | B15: -2068 | C15: 1859
A16: Podatek dochodowy zapłacony | B16: -173004 | C16: -234653 | D16: -291839 | E16: -417176
A17: III Przepływy pieniężne netto z działalności operacyjnej (I+/- II) | B17: =SUM(B4,B5) -> 1326331 | C17: =SUM(C4,C5) -> 1253422 | D17: =SUM(D4,D5) -> 1771540 | E17: =SUM(E4,E5) -> 2557453
A18: B.PRZEPŁYWY ŚRODKÓW PIENIĘŻNYCH Z DZIAŁALNOŚCI INWESTYCYJNEJ
A19: I Wpływy | B19: =SUM(B20:B22) -> 6676 | C19: =SUM(C20:C22) -> 12966 | D19: =SUM(D20:D22) -> 16572 | E19: =SUM(E20:E22) -> 10261 | H19: 2021 | I19: 2022 | J19: 2023 | K19: 2024
A20: Sprzedaż rzeczowych aktywów trwałych | B20: 4263 | C20: 6287 | D20: 5735 | E20: 2430 | G20: Przepływy pieniężne z działalności inwestycyjnej | H20: -1330728 | I20: -1434563 | J20: -1158256 | K20: -1596909
A21: Odsetki od udzielonych pożyczek | B21: 998 | C21: 4969 | D21: 9006 | E21: 5972
A22: Spłata udzielonych pożyczek | B22: 1415 | C22: 1710 | D22: 1831 | E22: 1859
A23: II Wydatki | B23: =SUM(B24:B26) -> 1337404 | C23: =SUM(C24:C26) -> 1447529 | D23: =SUM(D24:D26) -> 1174828 | E23: =SUM(E24:E26) -> 1607170
A24: Nabycie rzeczowych aktywów trwałych i aktywów niematerialnych | B24: 1335604 | C24: 1445905 | D24: 1172863 | E24: 1561914
A25: Udzielenie pożyczek | B25: 1800 | C25: 1624 | D25: 1965 | E25: 2419
A26: Nabycie jednostek zależnych | E26: 42837
A27: III. Przepływy pieniężne netto z działalności inwestycyjnej (I+/- II) | B27: =B19-B23 -> -1330728 | C27: =C19-C23 -> -1434563 | D27: =D19-D23 -> -1158256 | E27: =E19-E23 -> -1596909
A28: C. PRZEPŁYWY ŚRODKÓW PIENIĘŻNYCH Z DZIAŁALNOŚCI FINANSOWEJ
A29: I. Wpływy | B29: =SUM(B30:B31) -> 257636 | C29: =SUM(C30:C31) -> 818366 | D29: =SUM(D30:D30) -> 61378 | E29: =SUM(E30:E30) -> 199961
A30: Wpływy z zaciągniętych kredytów i pożyczek | B30: 57636 | C30: 648366 | D30: 61378 | E30: 199961
A31: Emisja dłuznych papierów wartościowych | B31: 200000 | C31: 170000
A32: II. Wydatki | B32: =SUM(B33:B36) -> 315042 | C32: =SUM(C33:C36) -> 673122 | D32: =SUM(D33:D36) -> 838991 | E32: =SUM(E33:E36) -> 487872
A33: Płatności z tytułu leasingu | B33: 47224 | C33: 47531 | D33: 25837 | E33: 43861
A34: Spłata kredytów bankowych | B34: 221173 | C34: 326529 | D34: 414180 | E34: 322719
A35: Wykup dłużnych papierów wartościowych | B35: 0 | C35: 170000 | D35: 250000 | E35: 0
A36: Odsetki zapłacone od kredytów i pożyczek | B36: 46645 | C36: 129062 | D36: 148974 | E36: 121292
A37: III. Przepływy pieniężne netto z działalności finansowej (I+/- II) | B37: =B29-B32 -> -57406 | C37: =C29-C32 -> 145244 | D37: =D29-D32 -> -777613 | E37: =E29-E32 -> -287911 | H37: 2021 | I37: 2022 | J37: 2023 | K37: 2024
A38: D. PRZEPŁYWY PIENIĘŻNE NETTO, RAZEM (AIII+/-BIII+/-CIII) | B38: =SUM(B17,B27,B37) -> -61803 | C38: =SUM(C17,C27,C37) -> -35897 | D38: =SUM(D17,D27,D37) -> -164329 | E38: =SUM(E17,E27,E37) -> 672633 | G38: Przepływy pieniężne z działalności finansowej | H38: -57406 | I38: 145244 | J38: -777613 | K38: -287911
A39: F. ŚRODKI PIENIĘŻNE NA POCZĄTEK OKRESU | B39: 480418 | C39: 418615 | D39: 1055351 | E39: 382718
A40: G. ŚRODKI PIENIĘŻNE NA KONIEC OKRESU | B40: =SUM(B38,B39) -> 418615 | C40: =SUM(C38,C39) -> 382718 | D40: =SUM(D38,D39) -> 891022 | E40: =SUM(E38,E39) -> 1055351
...

Sheet Wskaźniki finansowe
V3: Źródło: Opracowanie własne na podstawie danych pochodzących ze sprawozdań jednostkowych Spółki za lata 2019-2022.
AE5: 2021 | AF5: 2022 | AG5: 2023 | AH5: 2024 | AL5: 2021 | AM5: 2022 | AN5: 2023 | AO5: 2024
Y6: 2021 | Z6: 2022 | AA6: 2023 | AB6: 2024 | AD6: ZADŁUŻENIE OGÓŁEM ZOB.O/AO | AE6: 0.57171281 | AF6: 0.5330717 | AG6: 0.4598704 | AH6: 0.45599371 | AK6: ZADŁUŻENIE DŁUGOTERMINOWE ZOB.DŁ/KW | AL6: 0.35594019 | AM6: 0.26384545 | AN6: 0.159333 | AO6: 0.080522067
C7: Wskaźniki PŁYNNOŚCI | D7: 2021 | E7: 2022 | F7: 2023 | G7: 2024 | L7: 2021 | M7: 2022 | N7: 2023 | O7: 2024 | X7: WSK. KREDYTU KUPIECKIEGO | Y7: 0.058683377 | Z7: 0.098376673 | AA7: 0.1067159 | AB7: 0.086308914
C8: WBPF | D8: 0.66050892 | E8: 0.73349942 | F8: 0.83859739 | G8: 0.82473352 | K8: WBPF | L8: 0.66050892 | M8: 0.73349942 | N8: 0.83859739 | O8: 0.82473352 | X8: WSK. CYKLU ZAPASÓW | Y8: 37.003909 | Z8: 35.974835 | AA8: 37.013161 | AB8: 37.894641
C9: WPP | D9: 0.20353135 | E9: 0.19726367 | F9: 0.15835514 | G9: 0.25227756 | X9: WSK. CYKLU NALEŻNOŚCI | Y9: 3.8799786 | Z9: 4.9972634 | AA9: 4.6341019 | AB9: 4.6298341
C10: WŚP | D10: 0.13928127 | E10: 0.10371405 | F10: 0.056296083 | G10: 0.16552982 | X10: WSK. CYKLU ZOBOW.HANDLOWYCH | Y10: 66.117166 | Z10: 50.797239 | AA10: 43.424663 | AB10: 53.642595
C11: WSK. KREDYTU KUPIECKIEGO | D11: 0.058683377 | E11: 0.098376673 | F11: 0.1067159 | G11: 0.086308914
C12: WSK. CYKLU ZAPASÓW | D12: 37.003909 | E12: 35.974835 | F12: 37.013161 | G12: 37.894641
C13: WSK. CYKLU NALEŻNOŚCI | D13: 3.8799786 | E13: 4.9972634 | F13: 4.6341019 | G13: 4.6298341
C14: WSK. CYKLU ZOBOW.HANDLOWYCH | D14: 66.117166 | E14: 50.797239 | F14: 43.424663 | G14: 53.642595
C15: WSK.CYKLU KO | D15: -27.490402 | E15: -17.878917 | F15: -8.7821959 | G15: -11.814587 | Q15: Wskaźnik płynności przyspieszonej (WPP
C16: WSK. CYKLU ŚRODKÓW PIENIĘŻN. | D16: -25.233278 | E16: -9.8251406 | F16: -1.7773999 | G16: -11.11812 | L16: 2021 | M16: 2022 | N16: 2023 | O16: 2024
K17: WPP | L17: 0.20353135 | M17: 0.19726367 | N17: 0.15835514 | O17: 0.25227756
C22: Wskaźniki ZADŁUŻENIA | D22: 2021 | E22: 2022 | F22: 2023 | G22: 2024
C23: ZADŁUŻENIE OGÓŁEM ZOB.O/AO | D23: 0.57171281 | E23: 0.5330717 | F23: 0.4598704 | G23: 0.45599371
C24: ZADŁUŻENIE KAPITAŁU WŁASNEGOZOB.O/KW | D24: 1.3348819 | E24: 1.1416565 | F24: 0.85140753 | G24: 0.84025873 | BH24: ROTACJI AKTYWÓW OGÓŁEM | BI24: 1.8639819 | BJ24: 2.1994327 | BK24: 2.4732087 | BL24: 2.2422069
C25: ZADŁUŻENIE DŁUGOTERMINOWE ZOB.DŁ/KW | D25: 0.35594019 | E25: 0.26384545 | F25: 0.159333 | G25: 0.080522067 | BH25: ROTACJI AKTYWÓW TRWAŁYCH | BI25: 2.5778733 | BJ25: 3.1449352 | BK25: 3.6025089 | BL25: 3.3974591
C26: Zysk strata netto | D26: 805303 | F26: 1132087 | H26: 1405327 | I26: 1505729 | AE26: 2021 | AF26: 2022 | AG26: 2023 | AH26: 2024 | BH26: ROTACJI AKTYWÓW OBROTOWYCH | BI26: 6.7308683 | BJ26: 7.3157639 | BK26: 7.8896259 | BL26: 6.5940637
C27: Przychody ze sprzedaży | D27: 13362012 | F27: 19801622 | H27: 25666255 | I27: 29273792 | Y27: Kształtowanie się wskaźników cykli | AD27: ZADŁUŻENIE KAPITAŁU WŁASNEGOZOB.O/KW | AE27: 1.3348819 | AF27: 1.1416565 | AG27: 0.85140753 | AH27: 0.84025873
L28: 2021 | M28: 2022 | N28: 2023 | O28: 2024 | Y28: 2021 | Z28: 2022 | AA28: 2023 | AB28: 2024
K29: WŚP | L29: 0.13928127 | M29: 0.10371405 | N29: 0.056296083 | O29: 0.16552982 | X29: WSK.CYKLU KAPITAŁU OBROTOWEGO | Y29: -27.490402 | Z29: -17.878917 | AA29: -8.7821959 | AB29: -11.814587
C30: Wskaźniki RENTOWNOŚCI | D30: 2019 | E30: 2020 | F30: 2021 | G30: 2022 | X30: WSK. CYKLU ŚRODKÓW PIENIĘŻN. | Y30: -25.233278 | Z30: -9.8251406 | AA30: -1.7773999 | AB30: -11.11812
C31: ROS (sales)Z NETTO/WART SPRZED | D31: 0.060268094 | E31: 0.057171428 | F31: 0.054753878 | G31: 0.051436076
C32: ROA (assets)Z. NETTO/AO | D32: 0.11233864 | E32: 0.12574471 | F32: 0.13541777 | G32: 0.11533033
C33: ROE (equity) ZYSK/KW | D33: 0.26229745 | E33: 0.26930196 | F33: 0.25071348 | G33: 0.21251897
C35: Koszty działalności operacyjnej | D35: 221083 | F35: 487753 | H35: 384522 | I35: 404675
C36: WSKAŹNIKI SPRAWNOŚCI DZIAŁANIA (EFEKTYWNOŚCI GOSPODAROWANIA) | D36: 2021 | E36: 2022 | F36: 2023 | G36: 2024
C37: OPERACYJNOŚCI (koszty bezpośrednie sprzedaży) | D37: 0.75125977 | E37: 0.75946455 | F37: 0.76916009 | G37: 0.76734961
C38: KONTROLI KOSZTÓW sprzedaży | D38: 0.16329599 | E38: 0.15554589 | F38: 0.15110974 | G38: 0.15982613
C39: KONTROLI KOSZTÓW zarządu | D39: 0.0087774955 | E39: 0.0072325893 | F39: 0.0067690436 | G39: 0.0079816445
C40: ROTACJI AKTYWÓW OGÓŁEM | D40: 1.8639819 | E40: 2.1994327 | F40: 2.4732087 | G40: 2.2422069
C41: ROTACJI AKTYWÓW TRWAŁYCH | D41: 2.5778733 | E41: 3.1449352 | F41: 3.6025089 | G41: 3.3974591
C42: ROTACJI AKTYWÓW OBROTOWYCH | D42: 6.7308683 | E42: 7.3157639 | F42: 7.8896259 | G42: 6.5940637
C43: ROTACJI ZAPASÓW | D43: 9.7287018 | E43: 10.006995 | F43: 9.72627 | G43: 9.500024
C44: ROTACJI NALEŻNOŚCI | D44: 92.784018 | E44: 72.039429 | F44: 77.684956 | G44: 77.756566
AE49: 2021 | AF49: 2022 | AG49: 2023 | AH49: 2024
AD50: ZADŁUŻENIE DŁUGOTERMINOWE ZOB.DŁ/KW | AE50: 0.35594019 | AF50: 0.26384545 | AG50: 0.159333 | AH50: 0.080522067
D58: 2021 | E58: 2022 | F58: 2023 | G58: 2024
C59: OPERACYJNOŚCI (koszty bezpośrednie sprzedaży) | D59: 0.75125977 | E59: 0.75946455 | F59: 0.76916009 | G59: 0.76734961
...

Sheet Sieć sklepów
D2: 2024 | E2: 2023 | F2: 2022 | G2: 2021 | H2: 2020 | I2: 2019 | J2: 2018 | K2: 2017 | L2: 2016 | M2: 2015
C3: Łączna liczba sklepów | D3: 2688 | E3: 2406 | F3: 2156 | G3: 1815 | H3: 1473 | I3: 1218 | J3: 977 | K3: 775 | L3: 628 | M3: 511
C4: Powierzchnia sprzedaży(tysiące metrów kwadratowych) | D4: 1061 | E4: 948 | F4: 848 | G4: 710 | H4: 573 | I4: 472 | J4: 376 | K4: 295 | L4: 238 | M4: 193
D14: 2024 | E14: 2023 | F14: 2022 | G14: 2021
C15: Świeże produkty spożywcze | D15: 0.4 | E15: 0.4 | F15: 0.39 | G15: 0.37
C16: Inne artykuły spożywcze | D16: 0.48 | E16: 0.48 | F16: 0.49 | G16: 0.5
C17: Produkty inne niż spożywcze | D17: 0.12 | E17: 0.12 | F17: 0.12 | G17: 0.13
